<?xml version="1.0" ?>
<sdf version="1.6">
  <model name="car_robot">
    <static>false</static>

    <!-- Base Link -->
    <link name="base_link">
      <pose>0 0 0 0 0 0</pose>
      <inertial>
        <mass>10.0</mass>
        <inertia>
          <ixx>0.1</ixx>
          <ixy>0.0</ixy>
          <ixz>0.0</ixz>
          <iyy>0.1</iyy>
          <iyz>0.0</iyz>
          <izz>0.1</izz>
        </inertia>
      </inertial>
      <visual name="visual">
        <pose>0 0 0 0 0 0</pose>
        <geometry>
          <box>
            <size>1.0 0.6 0.2</size>
          </box>
        </geometry>
        <material>
          <ambient>0 0 1 1</ambient>
          <diffuse>0 0 1 1</diffuse>
        </material>
      </visual>
      <collision name="collision">
        <pose>0 0 0 0 0 0</pose>
        <geometry>
          <box>
            <size>1.0 0.6 0.2</size>
          </box>
        </geometry>
      </collision>
    </link>

    <!-- Front Left Wheel -->
    <link name="wheel_fl">
      <pose>0 0 0 0 0 0</pose>
      <inertial>
        <mass>1.0</mass>
        <inertia>
          <ixx>0.01</ixx>
          <ixy>0.0</ixy>
          <ixz>0.0</ixz>
          <iyy>0.01</iyy>
          <iyz>0.0</iyz>
          <izz>0.01</izz>
        </inertia>
      </inertial>
      <visual name="visual">
        <pose>0 0 0 0 0 0</pose>
        <geometry>
          <cylinder>
            <radius>0.15</radius>
            <length>0.1</length>
          </cylinder>
        </geometry>
        <material>
          <ambient>0 0 0 1</ambient>
          <diffuse>0 0 0 1</diffuse>
        </material>
      </visual>
      <collision name="collision">
        <pose>0 0 0 0 0 0</pose>
        <geometry>
          <cylinder>
            <radius>0.15</radius>
            <length>0.1</length>
          </cylinder>
        </geometry>
      </collision>
    </link>

    <!-- Front Right Wheel -->
    <link name="wheel_fr">
      <pose>0 0 0 0 0 0</pose>
      <inertial>
        <mass>1.0</mass>
        <inertia>
          <ixx>0.01</ixx>
          <ixy>0.0</ixy>
          <ixz>0.0</ixz>
          <iyy>0.01</iyy>
          <iyz>0.0</iyz>
          <izz>0.01</izz>
        </inertia>
      </inertial>
      <visual name="visual">
        <pose>0 0 0 0 0 0</pose>
        <geometry>
          <cylinder>
            <radius>0.15</radius>
            <length>0.1</length>
          </cylinder>
        </geometry>
        <material>
          <ambient>0 0 0 1</ambient>
          <diffuse>0 0 0 1</diffuse>
        </material>
      </visual>
      <collision name="collision">
        <pose>0 0 0 0 0 0</pose>
        <geometry>
          <cylinder>
            <radius>0.15</radius>
            <length>0.1</length>
          </cylinder>
        </geometry>
      </collision>
    </link>

    <!-- Rear Left Wheel -->
    <link name="wheel_rl">
      <pose>0 0 0 0 0 0</pose>
      <inertial>
        <mass>1.0</mass>
        <inertia>
          <ixx>0.01</ixx>
          <ixy>0.0</ixy>
          <ixz>0.0</ixz>
          <iyy>0.01</iyy>
          <iyz>0.0</iyz>
          <izz>0.01</izz>
        </inertia>
      </inertial>
      <visual name="visual">
        <pose>0 0 0 0 0 0</pose>
        <geometry>
          <cylinder>
            <radius>0.15</radius>
            <length>0.1</length>
          </cylinder>
        </geometry>
        <material>
          <ambient>0 0 0 1</ambient>
          <diffuse>0 0 0 1</diffuse>
        </material>
      </visual>
      <collision name="collision">
        <pose>0 0 0 0 0 0</pose>
        <geometry>
          <cylinder>
            <radius>0.15</radius>
            <length>0.1</length>
          </cylinder>
        </geometry>
      </collision>
    </link>

    <!-- Rear Right Wheel -->
    <link name="wheel_rr">
      <pose>0 0 0 0 0 0</pose>
      <inertial>
        <mass>1.0</mass>
        <inertia>
          <ixx>0.01</ixx>
          <ixy>0.0</ixy>
          <ixz>0.0</ixz>
          <iyy>0.01</iyy>
          <iyz>0.0</iyz>
          <izz>0.01</izz>
        </inertia>
      </inertial>
      <visual name="visual">
        <pose>0 0 0 0 0 0</pose>
        <geometry>
          <cylinder>
            <radius>0.15</radius>
            <length>0.1</length>
          </cylinder>
        </geometry>
        <material>
          <ambient>0 0 0 1</ambient>
          <diffuse>0 0 0 1</diffuse>
        </material>
      </visual>
      <collision name="collision">
        <pose>0 0 0 0 0 0</pose>
        <geometry>
          <cylinder>
            <radius>0.15</radius>
            <length>0.1</length>
          </cylinder>
        </geometry>
      </collision>
    </link>

    <!-- Joint: Front Left Wheel -->
    <joint name="joint_wheel_fl" type="revolute">
      <parent>base_link</parent>
      <child>wheel_fl</child>
      <pose>0.4 0.3 -0.1 0 0 0</pose>
      <axis>
        <xyz>0 1 0</xyz>
        <limit>
          <lower>-3.14</lower>
          <upper>3.14</upper>
          <effort>100</effort>
          <velocity>10</velocity>
        </limit>
      </axis>
    </joint>

    <!-- Joint: Front Right Wheel -->
    <joint name="joint_wheel_fr" type="revolute">
      <parent>base_link</parent>
      <child>wheel_fr</child>
      <pose>0.4 -0.3 -0.1 0 0 0</pose>
      <axis>
        <xyz>0 1 0</xyz>
        <limit>
          <lower>-3.14</lower>
          <upper>3.14</upper>
          <effort>100</effort>
          <velocity>10</velocity>
        </limit>
      </axis>
    </joint>

    <!-- Joint: Rear Left Wheel -->
    <joint name="joint_wheel_rl" type="revolute">
      <parent>base_link</parent>
      <child>wheel_rl</child>
      <pose>-0.4 0.3 -0.1 0 0 0</pose>
      <axis>
        <xyz>0 1 0</xyz>
        <limit>
          <lower>-3.14</lower>
          <upper>3.14</upper>
          <effort>100</effort>
          <velocity>10</velocity>
        </limit>
      </axis>
    </joint>

    <!-- Joint: Rear Right Wheel -->
    <joint name="joint_wheel_rr" type="revolute">
      <parent>base_link</parent>
      <child>wheel_rr</child>
      <pose>-0.4 -0.3 -0.1 0 0 0</pose>
      <axis>
        <xyz>0 1 0</xyz>
        <limit>
          <lower>-3.14</lower>
          <upper>3.14</upper>
          <effort>100</effort>
          <velocity>10</velocity>
        </limit>
      </axis>
    </joint>

  </model>
</sdf>
