<?xml version="1.0" ?>
<sdf version="1.6">
  <model name="manipulator_robot">
    <static>false</static>

    <!-- Base of the Manipulator -->
    <link name="base_link">
      <pose>0 0 0 0 0 0</pose>
      <inertial>
        <mass>5.0</mass>
        <inertia>
          <ixx>0.05</ixx>
          <ixy>0.0</ixy>
          <ixz>0.0</ixz>
          <iyy>0.05</iyy>
          <iyz>0.0</iyz>
          <izz>0.05</izz>
        </inertia>
      </inertial>
      <visual name="visual">
        <pose>0 0 0 0 0 0</pose>
        <geometry>
          <cylinder>
            <radius>0.2</radius>
            <length>0.1</length>
          </cylinder>
        </geometry>
        <material>
          <ambient>0 1 0 1</ambient>
          <diffuse>0 1 0 1</diffuse>
        </material>
      </visual>
      <collision name="collision">
        <pose>0 0 0 0 0 0</pose>
        <geometry>
          <cylinder>
            <radius>0.2</radius>
            <length>0.1</length>
          </cylinder>
        </geometry>
      </collision>
    </link>

    <!-- First Arm Link -->
    <link name="arm_link1">
      <pose>0 0 0 0 0 0</pose>
      <inertial>
        <mass>2.0</mass>
        <!-- The inertial pose indicates the center of mass relative to the link frame -->
        <pose>0 0 0.25 0 0 0</pose>
        <inertia>
          <ixx>0.02</ixx>
          <ixy>0.0</ixy>
          <ixz>0.0</ixz>
          <iyy>0.02</iyy>
          <iyz>0.0</iyz>
          <izz>0.02</izz>
        </inertia>
      </inertial>
      <visual name="visual">
        <pose>0 0 0 0 0 0</pose>
        <geometry>
          <box>
            <size>0.1 0.1 0.5</size>
          </box>
        </geometry>
        <material>
          <ambient>1 0 0 1</ambient>
          <diffuse>1 0 0 1</diffuse>
        </material>
      </visual>
      <collision name="collision">
        <pose>0 0 0 0 0 0</pose>
        <geometry>
          <box>
            <size>0.1 0.1 0.5</size>
          </box>
        </geometry>
      </collision>
    </link>

    <!-- Second Arm Link -->
    <link name="arm_link2">
      <pose>0 0 0 0 0 0</pose>
      <inertial>
        <mass>1.5</mass>
        <pose>0 0 0.2 0 0 0</pose>
        <inertia>
          <ixx>0.015</ixx>
          <ixy>0.0</ixy>
          <ixz>0.0</ixz>
          <iyy>0.015</iyy>
          <iyz>0.0</iyz>
          <izz>0.015</izz>
        </inertia>
      </inertial>
      <visual name="visual">
        <pose>0 0 0 0 0 0</pose>
        <geometry>
          <box>
            <size>0.1 0.1 0.4</size>
          </box>
        </geometry>
        <material>
          <ambient>1 0.65 0 1</ambient>
          <diffuse>1 0.65 0 1</diffuse>
        </material>
      </visual>
      <collision name="collision">
        <pose>0 0 0 0 0 0</pose>
        <geometry>
          <box>
            <size>0.1 0.1 0.4</size>
          </box>
        </geometry>
      </collision>
    </link>

    <!-- Joint: Base to First Arm Link -->
    <joint name="joint_base_to_arm1" type="revolute">
      <parent>base_link</parent>
      <child>arm_link1</child>
      <pose>0 0 0.1 0 0 0</pose>
      <axis>
        <xyz>0 1 0</xyz>
        <limit>
          <lower>-1.57</lower>
          <upper>1.57</upper>
          <effort>10</effort>
          <velocity>0.5</velocity>
        </limit>
      </axis>
    </joint>

    <!-- Joint: First Arm Link to Second Arm Link -->
    <joint name="joint_arm1_to_arm2" type="revolute">
      <parent>arm_link1</parent>
      <child>arm_link2</child>
      <pose>0 0 0.5 0 0 0</pose>
      <axis>
        <xyz>0 1 0</xyz>
        <limit>
          <lower>-1.57</lower>
          <upper>1.57</upper>
          <effort>10</effort>
          <velocity>0.5</velocity>
        </limit>
      </axis>
    </joint>

  </model>
</sdf>
